Internal Server Error: /bing/
Traceback (most recent call last):
  File "C:\virtualenvs\myenv\lib\site-packages\django\core\handlers\exception.py", line 41, in inner
    response = get_response(request)
  File "C:\virtualenvs\myenv\lib\site-packages\django\core\handlers\base.py", line 187, in _get_response
    response = self.process_exception_by_middleware(e, request)
  File "C:\virtualenvs\myenv\lib\site-packages\django\core\handlers\base.py", line 185, in _get_response
    response = wrapped_callback(request, *callback_args, **callback_kwargs)
  File "C:\virtualenvs\myenv\lib\site-packages\django\views\decorators\csrf.py", line 58, in wrapped_view
    return view_func(*args, **kwargs)
  File "C:\virtualenvs\myenv\lib\site-packages\django\views\generic\base.py", line 68, in view
    return self.dispatch(request, *args, **kwargs)
  File "C:\virtualenvs\myenv\lib\site-packages\rest_framework\views.py", line 483, in dispatch
    response = self.handle_exception(exc)
  File "C:\virtualenvs\myenv\lib\site-packages\rest_framework\views.py", line 443, in handle_exception
    self.raise_uncaught_exception(exc)
  File "C:\virtualenvs\myenv\lib\site-packages\rest_framework\views.py", line 480, in dispatch
    response = handler(request, *args, **kwargs)
  File "C:\virtualenvs\myenv\lib\site-packages\rest_framework\decorators.py", line 52, in handler
    return func(*args, **kwargs)
  File ".\tracer1\views.py", line 123, in bing_list
    print "{" + str(request.POST['nam'])
  File "C:\virtualenvs\myenv\lib\site-packages\django\utils\datastructures.py", line 85, in __getitem__
    raise MultiValueDictKeyError(repr(key))
MultiValueDictKeyError: "'nam'"
Internal Server Error: /bing/
Traceback (most recent call last):
  File "C:\virtualenvs\myenv\lib\site-packages\django\core\handlers\exception.py", line 41, in inner
    response = get_response(request)
  File "C:\virtualenvs\myenv\lib\site-packages\django\core\handlers\base.py", line 187, in _get_response
    response = self.process_exception_by_middleware(e, request)
  File "C:\virtualenvs\myenv\lib\site-packages\django\core\handlers\base.py", line 185, in _get_response
    response = wrapped_callback(request, *callback_args, **callback_kwargs)
  File "C:\virtualenvs\myenv\lib\site-packages\django\views\decorators\csrf.py", line 58, in wrapped_view
    return view_func(*args, **kwargs)
  File "C:\virtualenvs\myenv\lib\site-packages\django\views\generic\base.py", line 68, in view
    return self.dispatch(request, *args, **kwargs)
  File "C:\virtualenvs\myenv\lib\site-packages\rest_framework\views.py", line 483, in dispatch
    response = self.handle_exception(exc)
  File "C:\virtualenvs\myenv\lib\site-packages\rest_framework\views.py", line 443, in handle_exception
    self.raise_uncaught_exception(exc)
  File "C:\virtualenvs\myenv\lib\site-packages\rest_framework\views.py", line 480, in dispatch
    response = handler(request, *args, **kwargs)
  File "C:\virtualenvs\myenv\lib\site-packages\rest_framework\decorators.py", line 52, in handler
    return func(*args, **kwargs)
  File ".\tracer1\views.py", line 123, in bing_list
    print "{" + str(request.POST['nam'])
  File "C:\virtualenvs\myenv\lib\site-packages\django\utils\datastructures.py", line 85, in __getitem__
    raise MultiValueDictKeyError(repr(key))
MultiValueDictKeyError: "'nam'"
Internal Server Error: /bing/
Traceback (most recent call last):
  File "C:\virtualenvs\myenv\lib\site-packages\django\core\handlers\exception.py", line 41, in inner
    response = get_response(request)
  File "C:\virtualenvs\myenv\lib\site-packages\django\core\handlers\base.py", line 187, in _get_response
    response = self.process_exception_by_middleware(e, request)
  File "C:\virtualenvs\myenv\lib\site-packages\django\core\handlers\base.py", line 185, in _get_response
    response = wrapped_callback(request, *callback_args, **callback_kwargs)
  File "C:\virtualenvs\myenv\lib\site-packages\django\views\decorators\csrf.py", line 58, in wrapped_view
    return view_func(*args, **kwargs)
  File "C:\virtualenvs\myenv\lib\site-packages\django\views\generic\base.py", line 68, in view
    return self.dispatch(request, *args, **kwargs)
  File "C:\virtualenvs\myenv\lib\site-packages\rest_framework\views.py", line 483, in dispatch
    response = self.handle_exception(exc)
  File "C:\virtualenvs\myenv\lib\site-packages\rest_framework\views.py", line 443, in handle_exception
    self.raise_uncaught_exception(exc)
  File "C:\virtualenvs\myenv\lib\site-packages\rest_framework\views.py", line 480, in dispatch
    response = handler(request, *args, **kwargs)
  File "C:\virtualenvs\myenv\lib\site-packages\rest_framework\decorators.py", line 52, in handler
    return func(*args, **kwargs)
  File ".\tracer1\views.py", line 123, in bing_list
    print "{" + str(request.POST['nam'])
  File "C:\virtualenvs\myenv\lib\site-packages\django\utils\datastructures.py", line 85, in __getitem__
    raise MultiValueDictKeyError(repr(key))
MultiValueDictKeyError: "'nam'"
Internal Server Error: /facebook/
Traceback (most recent call last):
  File "C:\virtualenvs\myenv\lib\site-packages\django\core\handlers\exception.py", line 41, in inner
    response = get_response(request)
  File "C:\virtualenvs\myenv\lib\site-packages\django\core\handlers\base.py", line 187, in _get_response
    response = self.process_exception_by_middleware(e, request)
  File "C:\virtualenvs\myenv\lib\site-packages\django\core\handlers\base.py", line 185, in _get_response
    response = wrapped_callback(request, *callback_args, **callback_kwargs)
  File "C:\virtualenvs\myenv\lib\site-packages\django\views\decorators\csrf.py", line 58, in wrapped_view
    return view_func(*args, **kwargs)
  File "C:\virtualenvs\myenv\lib\site-packages\django\views\generic\base.py", line 68, in view
    return self.dispatch(request, *args, **kwargs)
  File "C:\virtualenvs\myenv\lib\site-packages\rest_framework\views.py", line 483, in dispatch
    response = self.handle_exception(exc)
  File "C:\virtualenvs\myenv\lib\site-packages\rest_framework\views.py", line 443, in handle_exception
    self.raise_uncaught_exception(exc)
  File "C:\virtualenvs\myenv\lib\site-packages\rest_framework\views.py", line 480, in dispatch
    response = handler(request, *args, **kwargs)
  File "C:\virtualenvs\myenv\lib\site-packages\rest_framework\decorators.py", line 52, in handler
    return func(*args, **kwargs)
  File ".\tracer1\views.py", line 31, in facebook_list
    data = fb.profile_list(name=request.POST.get('nam'))
  File ".\tracer1\socialmedia\fb_search.py", line 66, in profile_list
    temp.update({"Name": nam.encode("ascii")})
UnicodeEncodeError: 'ascii' codec can't encode characters in position 1-29: ordinal not in range(128)
Internal Server Error: /linkedin/
Traceback (most recent call last):
  File "C:\virtualenvs\myenv\lib\site-packages\django\core\handlers\exception.py", line 41, in inner
    response = get_response(request)
  File "C:\virtualenvs\myenv\lib\site-packages\django\core\handlers\base.py", line 187, in _get_response
    response = self.process_exception_by_middleware(e, request)
  File "C:\virtualenvs\myenv\lib\site-packages\django\core\handlers\base.py", line 185, in _get_response
    response = wrapped_callback(request, *callback_args, **callback_kwargs)
  File "C:\virtualenvs\myenv\lib\site-packages\django\views\decorators\csrf.py", line 58, in wrapped_view
    return view_func(*args, **kwargs)
  File "C:\virtualenvs\myenv\lib\site-packages\django\views\generic\base.py", line 68, in view
    return self.dispatch(request, *args, **kwargs)
  File "C:\virtualenvs\myenv\lib\site-packages\rest_framework\views.py", line 483, in dispatch
    response = self.handle_exception(exc)
  File "C:\virtualenvs\myenv\lib\site-packages\rest_framework\views.py", line 443, in handle_exception
    self.raise_uncaught_exception(exc)
  File "C:\virtualenvs\myenv\lib\site-packages\rest_framework\views.py", line 480, in dispatch
    response = handler(request, *args, **kwargs)
  File "C:\virtualenvs\myenv\lib\site-packages\rest_framework\decorators.py", line 52, in handler
    return func(*args, **kwargs)
  File ".\tracer1\views.py", line 45, in linkedIn_list
    data = ln.link(nam=respo)
  File ".\tracer1\socialmedia\link_search.py", line 14, in link
    "&lastName=" + nam.split(" ", 1)[1]
IndexError: list index out of range
Internal Server Error: /linkedin/
Traceback (most recent call last):
  File "C:\virtualenvs\myenv\lib\site-packages\django\core\handlers\exception.py", line 41, in inner
    response = get_response(request)
  File "C:\virtualenvs\myenv\lib\site-packages\django\core\handlers\base.py", line 187, in _get_response
    response = self.process_exception_by_middleware(e, request)
  File "C:\virtualenvs\myenv\lib\site-packages\django\core\handlers\base.py", line 185, in _get_response
    response = wrapped_callback(request, *callback_args, **callback_kwargs)
  File "C:\virtualenvs\myenv\lib\site-packages\django\views\decorators\csrf.py", line 58, in wrapped_view
    return view_func(*args, **kwargs)
  File "C:\virtualenvs\myenv\lib\site-packages\django\views\generic\base.py", line 68, in view
    return self.dispatch(request, *args, **kwargs)
  File "C:\virtualenvs\myenv\lib\site-packages\rest_framework\views.py", line 483, in dispatch
    response = self.handle_exception(exc)
  File "C:\virtualenvs\myenv\lib\site-packages\rest_framework\views.py", line 443, in handle_exception
    self.raise_uncaught_exception(exc)
  File "C:\virtualenvs\myenv\lib\site-packages\rest_framework\views.py", line 480, in dispatch
    response = handler(request, *args, **kwargs)
  File "C:\virtualenvs\myenv\lib\site-packages\rest_framework\decorators.py", line 52, in handler
    return func(*args, **kwargs)
  File ".\tracer1\views.py", line 45, in linkedIn_list
    data = ln.link(nam=respo)
  File ".\tracer1\socialmedia\link_search.py", line 14, in link
    "&lastName=" + nam.split(" ", 1)[1]
IndexError: list index out of range
Internal Server Error: /linkedin/
Traceback (most recent call last):
  File "C:\virtualenvs\myenv\lib\site-packages\django\core\handlers\exception.py", line 41, in inner
    response = get_response(request)
  File "C:\virtualenvs\myenv\lib\site-packages\django\core\handlers\base.py", line 187, in _get_response
    response = self.process_exception_by_middleware(e, request)
  File "C:\virtualenvs\myenv\lib\site-packages\django\core\handlers\base.py", line 185, in _get_response
    response = wrapped_callback(request, *callback_args, **callback_kwargs)
  File "C:\virtualenvs\myenv\lib\site-packages\django\views\decorators\csrf.py", line 58, in wrapped_view
    return view_func(*args, **kwargs)
  File "C:\virtualenvs\myenv\lib\site-packages\django\views\generic\base.py", line 68, in view
    return self.dispatch(request, *args, **kwargs)
  File "C:\virtualenvs\myenv\lib\site-packages\rest_framework\views.py", line 483, in dispatch
    response = self.handle_exception(exc)
  File "C:\virtualenvs\myenv\lib\site-packages\rest_framework\views.py", line 443, in handle_exception
    self.raise_uncaught_exception(exc)
  File "C:\virtualenvs\myenv\lib\site-packages\rest_framework\views.py", line 480, in dispatch
    response = handler(request, *args, **kwargs)
  File "C:\virtualenvs\myenv\lib\site-packages\rest_framework\decorators.py", line 52, in handler
    return func(*args, **kwargs)
  File ".\tracer1\views.py", line 45, in linkedIn_list
    data = ln.link(nam=respo)
  File ".\tracer1\socialmedia\link_search.py", line 14, in link
    "&lastName=" + nam.split(" ", 1)[1]
IndexError: list index out of range
Internal Server Error: /linkedin/
Traceback (most recent call last):
  File "C:\virtualenvs\myenv\lib\site-packages\django\core\handlers\exception.py", line 41, in inner
    response = get_response(request)
  File "C:\virtualenvs\myenv\lib\site-packages\django\core\handlers\base.py", line 187, in _get_response
    response = self.process_exception_by_middleware(e, request)
  File "C:\virtualenvs\myenv\lib\site-packages\django\core\handlers\base.py", line 185, in _get_response
    response = wrapped_callback(request, *callback_args, **callback_kwargs)
  File "C:\virtualenvs\myenv\lib\site-packages\django\views\decorators\csrf.py", line 58, in wrapped_view
    return view_func(*args, **kwargs)
  File "C:\virtualenvs\myenv\lib\site-packages\django\views\generic\base.py", line 68, in view
    return self.dispatch(request, *args, **kwargs)
  File "C:\virtualenvs\myenv\lib\site-packages\rest_framework\views.py", line 483, in dispatch
    response = self.handle_exception(exc)
  File "C:\virtualenvs\myenv\lib\site-packages\rest_framework\views.py", line 443, in handle_exception
    self.raise_uncaught_exception(exc)
  File "C:\virtualenvs\myenv\lib\site-packages\rest_framework\views.py", line 480, in dispatch
    response = handler(request, *args, **kwargs)
  File "C:\virtualenvs\myenv\lib\site-packages\rest_framework\decorators.py", line 52, in handler
    return func(*args, **kwargs)
  File ".\tracer1\views.py", line 45, in linkedIn_list
    data = ln.link(nam=respo)
  File ".\tracer1\socialmedia\link_search.py", line 14, in link
    "&lastName=" + nam.split(" ", 1)[1]
IndexError: list index out of range
