Internal Server Error: /twitter/
Traceback (most recent call last):
  File "C:\virtualenvs\myenv\lib\site-packages\django\core\handlers\exception.py", line 41, in inner
    response = get_response(request)
  File "C:\virtualenvs\myenv\lib\site-packages\django\core\handlers\base.py", line 187, in _get_response
    response = self.process_exception_by_middleware(e, request)
  File "C:\virtualenvs\myenv\lib\site-packages\django\core\handlers\base.py", line 185, in _get_response
    response = wrapped_callback(request, *callback_args, **callback_kwargs)
  File "C:\virtualenvs\myenv\lib\site-packages\django\views\decorators\csrf.py", line 58, in wrapped_view
    return view_func(*args, **kwargs)
  File "C:\virtualenvs\myenv\lib\site-packages\django\views\generic\base.py", line 68, in view
    return self.dispatch(request, *args, **kwargs)
  File "C:\virtualenvs\myenv\lib\site-packages\rest_framework\views.py", line 485, in dispatch
    self.response = self.finalize_response(request, response, *args, **kwargs)
  File "C:\virtualenvs\myenv\lib\site-packages\rest_framework\views.py", line 405, in finalize_response
    % type(response)
AssertionError: Expected a `Response`, `HttpResponse` or `HttpStreamingResponse` to be returned from the view, but received a `<type 'NoneType'>`
